Workbook

Sheet Supuestos
A1: Clave | B1: Descripción | C1: Valor | D1: Unidad | E1: Placeholder | F1: Fuente / nota
A2: General
A3: horas | B3: Horas por mes | C3: 730 | D3: h | E3: no | F3: Convención de AWS
A4: region | B4: Región | C4: us-east-1 | E4: no | F4: S-01
A5: meses_pico | B5: Meses de pico al año (una semana, cuatro veces al año) | C5: 1 | D5: meses | E5: no | F5: S-02
A6: mult_pico | B6: Multiplicador de carga en pico | C6: 3 | D6: x | E6: no | F6: S-02
A7: factor | B7: Factor de carga mensual promedio = (12 - meses de pico + meses de pico x multiplicador) / 12 | C7: =(12-Supuestos!$C$5+Supuestos!$C$5*Supuestos!$C$6)/12 | D7: x | E7: no | F7: Se aplica al cómputo de ECS y a los volúmenes de tráfico
A8: req_min | B8: Solicitudes por minuto (promedio fuera de pico) | C8: 10000 | D8: req/min | E8: no | F8: Dato del escenario
A9: req_mes | B9: Solicitudes por mes, con el factor de pico | C9: =Supuestos!$C$8*60*Supuestos!$C$3*Supuestos!$C$7 | D9: solicitudes | E9: no | F9: Calculado
A10: Cómputo
A11: servicios | B11: Servicios de ECS (una tarea equivalente por servicio) | C11: 100 | D11: servicios | E11: no | F11: S-03
A12: vcpu | B12: vCPU promedio por servicio | C12: 2 | D12: vCPU | E12: no | F12: S-03, cota superior
A13: gb | B13: Memoria promedio por servicio | C13: 4 | D13: GB | E13: no | F13: S-03, cota superior
A14: p_fg_vcpu | B14: Fargate Linux ARM (Graviton): precio por vCPU-hora | C14: 0.03238 | D14: USD | E14: sí | F14: Verificar en calculadora
A15: p_fg_gb | B15: Fargate Linux ARM (Graviton): precio por GB-hora | C15: 0.00356 | D15: USD | E15: sí | F15: Verificar en calculadora
A16: signer_n | B16: Instancias del servicio de firma (Nitro Enclaves) | C16: 2 | D16: instancias | E16: no | F16: Una por zona; c9g.large soporta Nitro Enclaves
A17: p_signer | B17: c9g.large (Graviton5) Linux: precio por hora | C17: 0.0798 | D17: USD | E17: sí | F17: Verificar en calculadora
A18: Red
A19: alb_n | B19: ALB (uno por servicio) | C19: 100 | D19: ALB | E19: no | F19: S-03
A20: p_alb_h | B20: ALB: precio por hora | C20: 0.0225 | D20: USD | E20: sí | F20: Verificar en calculadora
A21: lcu | B21: LCU promedio total entre todos los ALB | C21: 50 | D21: LCU | E21: sí
A22: p_alb_lcu | B22: ALB: precio por LCU-hora | C22: 0.008 | D22: USD | E22: sí | F22: Verificar en calculadora
A23: cf_gb | B23: CloudFront: GB transferidos a internet por mes fuera de pico | C23: 2000 | D23: GB | E23: sí
A24: p_cf_gb | B24: CloudFront: precio por GB (sin capa gratuita) | C24: 0.085 | D24: USD | E24: sí | F24: Verificar en calculadora
A25: p_cf_req | B25: CloudFront: precio por millón de solicitudes HTTPS | C25: 1 | D25: USD | E25: sí | F25: Verificar en calculadora
A26: waf_reglas | B26: WAF: reglas | C26: 15 | D26: reglas | E26: sí
A27: p_waf_acl | B27: WAF: precio por web ACL al mes | C27: 5 | D27: USD | E27: sí | F27: Verificar en calculadora
A28: p_waf_regla | B28: WAF: precio por regla al mes | C28: 1 | D28: USD | E28: sí | F28: Verificar en calculadora
A29: p_waf_req | B29: WAF: precio por millón de solicitudes | C29: 0.6 | D29: USD | E29: sí | F29: Verificar en calculadora
A30: nat_n | B30: NAT gateways (uno por zona) | C30: 3 | D30: NAT | E30: sí | F30: Mismas Elastic IPs de hoy
A31: p_nat_h | B31: NAT: precio por hora | C31: 0.045 | D31: USD | E31: sí | F31: Verificar en calculadora
A32: nat_gb | B32: NAT: GB procesados por mes fuera de pico | C32: 3000 | D32: GB | E32: sí
A33: p_nat_gb | B33: NAT: precio por GB | C33: 0.045 | D33: USD | E33: sí | F33: Verificar en calculadora
A34: lat_svc | B34: VPC Lattice: servicios | C34: 100 | D34: servicios | E34: no | F34: Uno por servicio de ECS
A35: p_lat_svc | B35: VPC Lattice: precio por servicio-hora | C35: 0.025 | D35: USD | E35: sí | F35: Verificar en calculadora
A36: lat_gb | B36: VPC Lattice: GB procesados por mes fuera de pico | C36: 2000 | D36: GB | E36: sí
A37: p_lat_gb | B37: VPC Lattice: precio por GB | C37: 0.025 | D37: USD | E37: sí | F37: Verificar en calculadora
A38: p_lat_req | B38: VPC Lattice: precio por millón de solicitudes (sin cuota gratuita) | C38: 0.1 | D38: USD | E38: sí | F38: Verificar en calculadora
A39: vpn_asoc | B39: Client VPN: asociaciones de subred | C39: 2 | D39: asociaciones | E39: sí
A40: p_vpn_asoc | B40: Client VPN: precio por asociación-hora | C40: 0.1 | D40: USD | E40: sí | F40: Verificar en calculadora
...

Sheet Estimado
A1: Categoría | B1: Servicio | C1: Descripción | D1: Cantidad | E1: Unidad | F1: Precio unitario (USD) | G1: Costo mensual (USD) | H1: En calculadora | I1: ADR
A2: Cómputo | B2: ECS Fargate (ARM) | C2: vCPU-hora | D2: =Supuestos!$C$11*Supuestos!$C$12*Supuestos!$C$3*Supuestos!$C$7 | E2: vCPU-h | F2: =Supuestos!$C$14 | G2: =D2*F2 | H2: Sí | I2: ADR-013
A3: Cómputo | B3: ECS Fargate (ARM) | C3: GB-hora | D3: =Supuestos!$C$11*Supuestos!$C$13*Supuestos!$C$3*Supuestos!$C$7 | E3: GB-h | F3: =Supuestos!$C$15 | G3: =D3*F3 | H3: Sí | I3: ADR-013
A4: Cómputo | B4: EC2 c9g.large (Nitro Enclaves) | C4: Servicio de firma | D4: =Supuestos!$C$16*Supuestos!$C$3 | E4: instancia-h | F4: =Supuestos!$C$17 | G4: =D4*F4 | H4: Sí | I4: ADR-021
A5: Red | B5: ALB | C5: Horas | D5: =Supuestos!$C$19*Supuestos!$C$3 | E5: ALB-h | F5: =Supuestos!$C$20 | G5: =D5*F5 | H5: Sí | I5: ADR-018
A6: Red | B6: ALB | C6: LCU | D6: =Supuestos!$C$21*Supuestos!$C$3*Supuestos!$C$7 | E6: LCU-h | F6: =Supuestos!$C$22 | G6: =D6*F6 | H6: Sí | I6: ADR-018
A7: Red | B7: CloudFront | C7: Transferencia a internet | D7: =Supuestos!$C$23*Supuestos!$C$7 | E7: GB | F7: =Supuestos!$C$24 | G7: =D7*F7 | H7: Sí | I7: ADR-018
A8: Red | B8: CloudFront | C8: Solicitudes HTTPS | D8: =Supuestos!$C$9/1000000 | E8: millones | F8: =Supuestos!$C$25 | G8: =D8*F8 | H8: Sí | I8: ADR-018
A9: Red | B9: AWS WAF | C9: Web ACL y reglas | D9: =1 | E9: ACL | F9: =Supuestos!$C$27+Supuestos!$C$26*Supuestos!$C$28 | G9: =D9*F9 | H9: Sí | I9: ADR-018
A10: Red | B10: AWS WAF | C10: Solicitudes | D10: =Supuestos!$C$9/1000000 | E10: millones | F10: =Supuestos!$C$29 | G10: =D10*F10 | H10: Sí | I10: ADR-018
A11: Red | B11: NAT Gateway | C11: Horas | D11: =Supuestos!$C$30*Supuestos!$C$3 | E11: NAT-h | F11: =Supuestos!$C$31 | G11: =D11*F11 | H11: Sí | I11: ADR-020
A12: Red | B12: NAT Gateway | C12: GB procesados | D12: =Supuestos!$C$32*Supuestos!$C$7 | E12: GB | F12: =Supuestos!$C$33 | G12: =D12*F12 | H12: Sí | I12: ADR-020
A13: Red | B13: VPC Lattice | C13: Servicio-hora | D13: =Supuestos!$C$34*Supuestos!$C$3 | E13: servicio-h | F13: =Supuestos!$C$35 | G13: =D13*F13 | H13: Verificar | I13: ADR-017
A14: Red | B14: VPC Lattice | C14: GB procesados | D14: =Supuestos!$C$36*Supuestos!$C$7 | E14: GB | F14: =Supuestos!$C$37 | G14: =D14*F14 | H14: Verificar | I14: ADR-017
A15: Red | B15: VPC Lattice | C15: Solicitudes | D15: =Supuestos!$C$9/1000000 | E15: millones | F15: =Supuestos!$C$38 | G15: =D15*F15 | H15: Verificar | I15: ADR-017
A16: Red | B16: AWS Client VPN | C16: Asociaciones de subred | D16: =Supuestos!$C$39*Supuestos!$C$3 | E16: asociación-h | F16: =Supuestos!$C$40 | G16: =D16*F16 | H16: Sí | I16: ADR-019
A17: Red | B17: AWS Client VPN | C17: Conexiones | D17: =Supuestos!$C$41 | E17: conexión-h | F17: =Supuestos!$C$42 | G17: =D17*F17 | H17: Sí | I17: ADR-019
A18: Datos | B18: RDS PostgreSQL | C18: Instancias grandes Single-AZ | D18: =Supuestos!$C$44*Supuestos!$C$3 | E18: instancia-h | F18: =Supuestos!$C$45 | G18: =D18*F18 | H18: Sí | I18: ADR-014
A19: Datos | B19: RDS PostgreSQL | C19: Almacenamiento gp3 | D19: =Supuestos!$C$46 | E19: GB-mes | F19: =Supuestos!$C$47 | G19: =D19*F19 | H19: Sí | I19: ADR-014
A20: Datos | B20: OpenSearch Serverless NextGen | C20: Cómputo (OCU) | D20: =Supuestos!$C$48*Supuestos!$C$3 | E20: OCU-h | F20: =Supuestos!$C$49 | G20: =D20*F20 | H20: No | I20: ADR-015
A21: Datos | B21: OpenSearch Serverless NextGen | C21: Almacenamiento | D21: =Supuestos!$C$50 | E21: GB-mes | F21: =Supuestos!$C$51 | G21: =D21*F21 | H21: No | I21: ADR-015
A22: Llaves y secretos | B22: DynamoDB | C22: Lecturas de llaves cifradas (una por firma) | D22: =Supuestos!$C$53/1000000 | E22: millones | F22: =Supuestos!$C$54 | G22: =D22*F22 | H22: Sí | I22: ADR-021
A23: Llaves y secretos | B23: DynamoDB | C23: Escrituras y réplica global | D23: =Supuestos!$C$55/1000000 | E23: millones | F23: =Supuestos!$C$56 | G23: =D23*F23 | H23: Sí | I23: ADR-021
A24: Llaves y secretos | B24: DynamoDB | C24: Almacenamiento | D24: =Supuestos!$C$57 | E24: GB-mes | F24: =Supuestos!$C$58 | G24: =D24*F24 | H24: Sí | I24: ADR-021
A25: Llaves y secretos | B25: AWS KMS | C25: Llaves | D25: =Supuestos!$C$59 | E25: llaves | F25: =Supuestos!$C$60 | G25: =D25*F25 | H25: Sí | I25: ADR-021
A26: Llaves y secretos | B26: AWS KMS | C26: Solicitudes | D26: =Supuestos!$C$61/10000 | E26: 10 mil | F26: =Supuestos!$C$62 | G26: =D26*F26 | H26: Sí | I26: ADR-021
A27: Llaves y secretos | B27: Secrets Manager | C27: Secretos | D27: =Supuestos!$C$63 | E27: secretos | F27: =Supuestos!$C$64 | G27: =D27*F27 | H27: Sí | I27: ADR-024
A28: Observabilidad | B28: CloudWatch Logs | C28: Ingesta | D28: =Supuestos!$C$66*Supuestos!$C$7 | E28: GB | F28: =Supuestos!$C$67 | G28: =D28*F28 | H28: Sí | I28: ADR-028
A29: Observabilidad | B29: CloudWatch Logs | C29: Almacenamiento con retención | D29: =Supuestos!$C$68 | E29: GB-mes | F29: =Supuestos!$C$69 | G29: =D29*F29 | H29: Sí | I29: ADR-028
A30: Observabilidad | B30: S3 | C30: Archivo de logs | D30: =Supuestos!$C$70 | E30: GB-mes | F30: =Supuestos!$C$71 | G30: =D30*F30 | H30: Sí | I30: ADR-028
A31: Observabilidad | B31: Athena | C31: Consultas sobre logs archivados | D31: =Supuestos!$C$72 | E31: TB | F31: =Supuestos!$C$73 | G31: =D31*F31 | H31: Sí | I31: ADR-028
A32: Observabilidad | B32: CloudWatch Omni | C32: Evaluación | D32: =1 | E32: mes | F32: =Supuestos!$C$74 | G32: =D32*F32 | H32: No | I32: ADR-027
A33: Gobierno | B33: AWS Config | C33: Elementos de configuración | D33: =Supuestos!$C$76 | E33: elementos | F33: =Supuestos!$C$77 | G33: =D33*F33 | H33: Sí | I33: ADR-030
A34: Gobierno | B34: Security Hub | C34: Verificaciones | D34: =Supuestos!$C$78 | E34: verificaciones | F34: =Supuestos!$C$79 | G34: =D34*F34 | H34: Sí | I34: ADR-030
A35: Gobierno | B35: CloudTrail | C35: Eventos de datos | D35: =Supuestos!$C$80 | E35: millones | F35: =Supuestos!$C$81 | G35: =D35*F35 | H35: Sí | I35: ADR-030
A36: CI/CD | B36: CodePipeline V2 | C36: Minutos de acciones | D36: =Supuestos!$C$83 | E36: min | F36: =Supuestos!$C$84 | G36: =D36*F36 | H36: Sí | I36: ADR-025
A37: CI/CD | B37: CodeBuild (ARM) | C37: Minutos de build | D37: =Supuestos!$C$85 | E37: min | F37: =Supuestos!$C$86 | G37: =D37*F37 | H37: Sí | I37: ADR-025
A38: CI/CD | B38: ECR | C38: Almacenamiento con réplica | D38: =Supuestos!$C$87 | E38: GB-mes | F38: =Supuestos!$C$88 | G38: =D38*F38 | H38: Sí | I38: ADR-025
A39: DR | B39: RDS PostgreSQL (región de DR) | C39: Réplicas entre regiones del mismo tamaño | D39: =Supuestos!$C$44*Supuestos!$C$3 | E39: instancia-h | F39: =Supuestos!$C$45 | G39: =D39*F39 | H39: Sí | I39: ADR-031
A40: DR | B40: RDS PostgreSQL (región de DR) | C40: Almacenamiento de las réplicas | D40: =Supuestos!$C$46 | E40: GB-mes | F40: =Supuestos!$C$47 | G40: =D40*F40 | H40: Sí | I40: ADR-031
...

Sheet Recortes
A1: Elegido | B1: Recorte | C1: Línea base (USD / mes) | D1: Reducción | E1: Ahorro (USD / mes) | F1: Riesgo que agrega | G1: ADR afectado
A2: sí | B2: DR solo con copias de AWS Backup entre regiones, sin réplicas vivas | C2: =SUMIFS(Estimado!G2:G42,Estimado!A2:A42,"DR") | D2: 0.85 | E2: =C2*D2 | F2: El RPO pasa de minutos a horas y el RTO crece por la restauración de las bases. | G2: ADR-031
A3: sí | B3: Reemplazar VPC Lattice por ECS Service Connect | C3: =SUMIFS(Estimado!G2:G42,Estimado!B2:B42,"VPC Lattice") | D3: 0.9 | E3: =C3*D3 | F3: Se pierde la autorización de IAM entre servicios; la segmentación PCI queda solo en security groups. | G3: ADR-017
A4: ? | B4: Consolidar los 100 ALB en unos 10 compartidos con reglas por host | C4: =SUMIFS(Estimado!G2:G42,Estimado!B2:B42,"ALB",Estimado!C2:C42,"Horas") | D4: 0.9 | E4: =C4*D4 | F4: Un error de configuración o un pico en un ALB compartido afecta a varios servicios. | G4: ADR-018
A5: ? | B5: Fargate Spot para el 30 % de los servicios | C5: =SUMIFS(Estimado!G2:G42,Estimado!B2:B42,"ECS Fargate (ARM)") | D5: 0.21 | E5: =C5*D5 | F5: Interrupciones de tareas con dos minutos de aviso; solo para servicios tolerantes. | G5: ADR-013
A6: ? | B6: Compute Savings Plan a un año | C6: =SUMIFS(Estimado!G2:G42,Estimado!A2:A42,"Cómputo") | D6: 0.2 | E6: =C6*D6 | F6: Compromiso de gasto por un año aunque el uso baje con el rightsizing. | G6: ADR-013
B8: Ahorro de los recortes elegidos (marcar con 'sí') | E8: =SUMIFS(E2:E6,A2:A6,"sí")
