Workbook

Sheet Supuestos
A1: Clave | B1: Descripción | C1: Valor | D1: Unidad | E1: Placeholder | F1: Fuente / nota
A2: General
A3: horas | B3: Horas por mes | C3: 730 | D3: h | E3: no | F3: Convención de AWS
A4: region | B4: Región | C4: us-east-1 | E4: no | F4: S-01
A5: meses_pico | B5: Meses de pico al año (una semana, cuatro veces al año) | C5: 1 | D5: meses | E5: no | F5: Igual al objetivo (costos.xlsx)
A6: mult_pico | B6: Multiplicador de carga en pico | C6: 3 | D6: x | E6: no | F6: Igual al objetivo (costos.xlsx)
A7: factor | B7: Factor de carga mensual promedio = (12 - meses de pico + meses de pico x multiplicador) / 12 | C7: =(12-Supuestos!$C$5+Supuestos!$C$5*Supuestos!$C$6)/12 | D7: x | E7: no | F7: Igual al objetivo (costos.xlsx)
A8: req_min | B8: Solicitudes por minuto (promedio fuera de pico) | C8: 10000 | D8: req/min | E8: no | F8: Igual al objetivo (costos.xlsx)
A9: req_mes | B9: Solicitudes por mes, con el factor de pico | C9: =Supuestos!$C$8*60*Supuestos!$C$3*Supuestos!$C$7 | D9: solicitudes | E9: no | F9: Calculado
A10: Cómputo (ECS en Fargate x86, sin Graviton ni rightsizing)
A11: servicios | B11: Servicios de ECS (una tarea equivalente por servicio) | C11: 100 | D11: servicios | E11: no | F11: Igual al objetivo (costos.xlsx)
A12: vcpu | B12: vCPU promedio por servicio | C12: 2 | D12: vCPU | E12: no | F12: Igual al objetivo (costos.xlsx)
A13: gb | B13: Memoria promedio por servicio | C13: 4 | D13: GB | E13: no | F13: Igual al objetivo (costos.xlsx)
A14: p_fg_vcpu | B14: Fargate Linux x86: precio por vCPU-hora | C14: 0.04048 | D14: USD | E14: sí | F14: Verificar en calculadora
A15: p_fg_gb | B15: Fargate Linux x86: precio por GB-hora | C15: 0.004445 | D15: USD | E15: sí | F15: Verificar en calculadora
A16: Red
A17: alb_n | B17: ALB (uno por servicio) | C17: 100 | D17: ALB | E17: no | F17: Igual al objetivo (costos.xlsx)
A18: p_alb_h | B18: ALB: precio por hora | C18: 0.0225 | D18: USD | E18: sí | F18: Verificar en calculadora
A19: lcu | B19: LCU promedio total entre todos los ALB | C19: 50 | D19: LCU | E19: sí | F19: Igual al objetivo (costos.xlsx)
A20: p_alb_lcu | B20: ALB: precio por LCU-hora | C20: 0.008 | D20: USD | E20: sí | F20: Verificar en calculadora
A21: waf_reglas | B21: WAF: reglas | C21: 15 | D21: reglas | E21: sí | F21: Igual al objetivo (costos.xlsx)
A22: p_waf_acl | B22: WAF: precio por web ACL al mes | C22: 5 | D22: USD | E22: sí | F22: Verificar en calculadora
A23: p_waf_regla | B23: WAF: precio por regla al mes | C23: 1 | D23: USD | E23: sí | F23: Verificar en calculadora
A24: p_waf_req | B24: WAF: precio por millón de solicitudes | C24: 0.6 | D24: USD | E24: sí | F24: Verificar en calculadora
A25: nat_n | B25: NAT gateways | C25: 3 | D25: NAT | E25: sí | F25: Igual al objetivo (costos.xlsx)
A26: p_nat_h | B26: NAT: precio por hora | C26: 0.045 | D26: USD | E26: sí | F26: Verificar en calculadora
A27: nat_gb | B27: NAT: GB procesados por mes fuera de pico | C27: 3000 | D27: GB | E27: sí | F27: Igual al objetivo (costos.xlsx)
A28: p_nat_gb | B28: NAT: precio por GB | C28: 0.045 | D28: USD | E28: sí | F28: Verificar en calculadora
... A30: p_vpn | B30: VPN: precio por hora de la instancia, sin licencia (ej. c6i.large) | C30: 0.085 | D30: USD | E30: sí | F30: Verificar en calculadora
A31: Datos
A32: rds_n | B32: RDS PostgreSQL: instancias grandes en una zona | C32: 30 | D32: instancias | E32: no | F32: Igual al objetivo (costos.xlsx)
A33: p_rds | B33: RDS PostgreSQL db.r6i.xlarge Single-AZ: precio por hora | C33: 0.5 | D33: USD | E33: sí | F33: Verificar en calculadora
A34: rds_gb | B34: RDS: almacenamiento total | C34: 6000 | D34: GB | E34: sí | F34: Igual al objetivo (costos.xlsx)
A35: p_rds_gb | B35: RDS gp2 Single-AZ: precio por GB-mes | C35: 0.115 | D35: USD | E35: sí | F35: Verificar en calculadora
A36: os_data_n | B36: OpenSearch: nodos de datos | C36: 3 | D36: nodos | E36: sí | F36: 6? Configuración desconocida
A37: p_os_data | B37: OpenSearch: precio por hora del nodo de datos (r6g.large.search) | C37: 0.167 | D37: USD | E37: sí | F37: Verificar en calculadora
A38: os_master_n | B38: OpenSearch: nodos maestros dedicados | C38: 3 | D38: nodos | E38: sí | F38: 6?
A39: p_os_master | B39: OpenSearch: precio por hora del nodo maestro (m6g.large.search) | C39: 0.128 | D39: USD | E39: sí | F39: Verificar en calculadora
A40: os_gb | B40: OpenSearch: almacenamiento EBS total | C40: 100 | D40: GB | E40: no | F40: S-05
A41: p_os_gb | B41: OpenSearch: precio por GB-mes de EBS gp3 | C41: 0.122 | D41: USD | E41: sí | F41: Verificar en calculadora
...

Sheet Estimado
A1: Categoría | B1: Servicio | C1: Descripción | D1: Cantidad | E1: Unidad | F1: Precio unitario (USD) | G1: Costo mensual (USD)
A2: Cómputo | B2: ECS Fargate (x86) | C2: vCPU-hora | D2: =Supuestos!$C$11*Supuestos!$C$12*Supuestos!$C$3*Supuestos!$C$7 | E2: vCPU-h | F2: =Supuestos!$C$14 | G2: =D2*F2
A3: Cómputo | B3: ECS Fargate (x86) | C3: GB-hora | D3: =Supuestos!$C$11*Supuestos!$C$13*Supuestos!$C$3*Supuestos!$C$7 | E3: GB-h | F3: =Supuestos!$C$15 | G3: =D3*F3
A4: Red | B4: ALB | C4: Horas | D4: =Supuestos!$C$17*Supuestos!$C$3 | E4: ALB-h | F4: =Supuestos!$C$18 | G4: =D4*F4
A5: Red | B5: ALB | C5: LCU | D5: =Supuestos!$C$19*Supuestos!$C$3*Supuestos!$C$7 | E5: LCU-h | F5: =Supuestos!$C$20 | G5: =D5*F5
A6: Red | B6: AWS WAF | C6: Web ACL y reglas | D6: =1 | E6: ACL | F6: =Supuestos!$C$22+Supuestos!$C$21*Supuestos!$C$23 | G6: =D6*F6
A7: Red | B7: AWS WAF | C7: Solicitudes | D7: =Supuestos!$C$9/1000000 | E7: millones | F7: =Supuestos!$C$24 | G7: =D7*F7
A8: Red | B8: NAT Gateway | C8: Horas | D8: =Supuestos!$C$25*Supuestos!$C$3 | E8: NAT-h | F8: =Supuestos!$C$26 | G8: =D8*F8
A9: Red | B9: NAT Gateway | C9: GB procesados | D9: =Supuestos!$C$27*Supuestos!$C$7 | E9: GB | F9: =Supuestos!$C$28 | G9: =D9*F9
A10: Red | B10: VPN de terceros | C10: Instancia del appliance (licencia excluida) | D10: =Supuestos!$C$29*Supuestos!$C$3 | E10: instancia-h | F10: =Supuestos!$C$30 | G10: =D10*F10
A11: Datos | B11: RDS PostgreSQL | C11: Instancias grandes Single-AZ | D11: =Supuestos!$C$32*Supuestos!$C$3 | E11: instancia-h | F11: =Supuestos!$C$33 | G11: =D11*F11
A12: Datos | B12: RDS PostgreSQL | C12: Almacenamiento | D12: =Supuestos!$C$34 | E12: GB-mes | F12: =Supuestos!$C$35 | G12: =D12*F12
A13: Datos | B13: OpenSearch (dominio) | C13: Nodos de datos | D13: =Supuestos!$C$36*Supuestos!$C$3 | E13: nodo-h | F13: =Supuestos!$C$37 | G13: =D13*F13
A14: Datos | B14: OpenSearch (dominio) | C14: Nodos maestros | D14: =Supuestos!$C$38*Supuestos!$C$3 | E14: nodo-h | F14: =Supuestos!$C$39 | G14: =D14*F14
A15: Datos | B15: OpenSearch (dominio) | C15: Almacenamiento EBS | D15: =Supuestos!$C$40 | E15: GB-mes | F15: =Supuestos!$C$41 | G15: =D15*F15
A16: Llaves y secretos | B16: AWS KMS | C16: Llaves de uso general | D16: =Supuestos!$C$44 | E16: llaves | F16: =Supuestos!$C$45 | G16: =D16*F16
A17: Llaves y secretos | B17: AWS KMS | C17: Solicitudes | D17: =Supuestos!$C$46/10000 | E17: 10 mil | F17: =Supuestos!$C$47 | G17: =D17*F17
A18: Llaves y secretos | B18: Secrets Manager | C18: Secretos | D18: =Supuestos!$C$48 | E18: secretos | F18: =Supuestos!$C$49 | G18: =D18*F18
A19: Observabilidad | B19: CloudWatch Logs | C19: Ingesta | D19: =Supuestos!$C$51*Supuestos!$C$7 | E19: GB | F19: =Supuestos!$C$52 | G19: =D19*F19
A20: Observabilidad | B20: CloudWatch Logs | C20: Almacenamiento acumulado sin retención | D20: =Supuestos!$C$51*Supuestos!$C$7*Supuestos!$C$53 | E20: GB-mes | F20: =Supuestos!$C$54 | G20: =D20*F20
A21: Gobierno | B21: AWS Config / Security Hub | C21: No existe hoy | D21: =0 | E21: - | F21: =0 | G21: =D21*F21
A22: CI/CD | B22: Pipelines | C22: No existen hoy: cambios a mano | D22: =0 | E22: - | F22: =0 | G22: =D22*F22
A23: DR | B23: Segunda región | C23: No existe hoy | D23: =0 | E23: - | F23: =0 | G23: =D23*F23
A25: Resumen | G25: USD / mes
A26: Cómputo | G26: =SUMIFS(G2:G23,A2:A23,"Cómputo")
A27: Red | G27: =SUMIFS(G2:G23,A2:A23,"Red")
A28: Datos | G28: =SUMIFS(G2:G23,A2:A23,"Datos")
A29: Llaves y secretos | G29: =SUMIFS(G2:G23,A2:A23,"Llaves y secretos")
A30: Observabilidad | G30: =SUMIFS(G2:G23,A2:A23,"Observabilidad")
A31: Gobierno | G31: =SUMIFS(G2:G23,A2:A23,"Gobierno")
A32: CI/CD | G32: =SUMIFS(G2:G23,A2:A23,"CI/CD")
A33: DR | G33: =SUMIFS(G2:G23,A2:A23,"DR")
A34: Total mensual | G34: =SUM(G2:G23)
A35: Total anual | G35: =G34*12
A37: Bajo demanda, sin capa gratuita, todo como producción. Excluido: licencias de New Relic y de la VPN, plan de soporte de AWS, impuestos y costo del equipo.
